Message logged at 01/24/20 23:02:29 by Bot David8#4665 in Channel Direct Message with Vyryn#4618: with Content: ```py\nTraceback (most recent call last):\n  File "C:\Python37\lib\site-packages\discord\ext\commands\core.py", line 79, in wrapped\n    ret = await coro(*args, **kwargs)\n  File "C:\Users\Vyryn\PycharmProjects\davidbot\cogs\corp.py", line 294, in corp_register\n    await ctx.author.add_roles(ctx.guild.get_role(667268366456717332))\n  File "C:\Python37\lib\site-packages\discord\member.py", line 616, in add_roles\n    await req(guild_id, user_id, role.id, reason=reason)\n  File "C:\Python37\lib\site-packages\discord\http.py", line 218, in request\n    raise Forbidden(r, data)\ndiscord.errors.Forbidden: 403 FORBIDDEN (error code: 50013): Missing Permissions\n\nThe above exception was the direct cause of the following exception:\n\nTraceback (most recent call last):\n  File "C:\Python37\lib\site-packages\discord\ext\commands\bot.py", line 863, in invoke\n    await ctx.command.invoke(ctx)\n  File "C:\Python37\lib\site-packages\discord\ext\commands\core.py", line 728, in invoke\n    await injected(*ctx.args, **ctx.kwargs)\n  File "C:\Python37\lib\site-packages\discord\ext\commands\core.py", line 88, in wrapped\n    raise CommandInvokeError(exc) from exc\ndiscord.ext.commands.errors.CommandInvokeError: Command raised an exception: Forbidden: 403 FORBIDDEN (error code: 50013): Missing Permissions\n\n```
Message logged at 01/24/20 23:23:13 by Bot David8#4665 in Channel Direct Message with Vyryn#4618: with Content: ```py\nTraceback (most recent call last):\n  File "C:\Python37\lib\site-packages\discord\ext\commands\core.py", line 79, in wrapped\n    ret = await coro(*args, **kwargs)\n  File "C:\Users\Vyryn\PycharmProjects\davidbot\cogs\corp.py", line 369, in list_rsi_links\n    if channel.members.len < 1:\nAttributeError: 'list' object has no attribute 'len'\n\nThe above exception was the direct cause of the following exception:\n\nTraceback (most recent call last):\n  File "C:\Python37\lib\site-packages\discord\ext\commands\bot.py", line 863, in invoke\n    await ctx.command.invoke(ctx)\n  File "C:\Python37\lib\site-packages\discord\ext\commands\core.py", line 728, in invoke\n    await injected(*ctx.args, **ctx.kwargs)\n  File "C:\Python37\lib\site-packages\discord\ext\commands\core.py", line 88, in wrapped\n    raise CommandInvokeError(exc) from exc\ndiscord.ext.commands.errors.CommandInvokeError: Command raised an exception: AttributeError: 'list' object has no attribute 'len'\n\n```
Message logged at 01/24/20 23:23:30 by Bot David8#4665 in Channel Direct Message with Vyryn#4618: with Content: ```py\nTraceback (most recent call last):\n  File "C:\Python37\lib\site-packages\discord\ext\commands\core.py", line 79, in wrapped\n    ret = await coro(*args, **kwargs)\n  File "C:\Users\Vyryn\PycharmProjects\davidbot\cogs\corp.py", line 369, in list_rsi_links\n    if channel.members.length < 1:\nAttributeError: 'list' object has no attribute 'length'\n\nThe above exception was the direct cause of the following exception:\n\nTraceback (most recent call last):\n  File "C:\Python37\lib\site-packages\discord\ext\commands\bot.py", line 863, in invoke\n    await ctx.command.invoke(ctx)\n  File "C:\Python37\lib\site-packages\discord\ext\commands\core.py", line 728, in invoke\n    await injected(*ctx.args, **ctx.kwargs)\n  File "C:\Python37\lib\site-packages\discord\ext\commands\core.py", line 88, in wrapped\n    raise CommandInvokeError(exc) from exc\ndiscord.ext.commands.errors.CommandInvokeError: Command raised an exception: AttributeError: 'list' object has no attribute 'length'\n\n```
Message logged at 01/24/20 23:23:42 by Bot David8#4665 in Channel Direct Message with Vyryn#4618: with Content: ```py\nTraceback (most recent call last):\n  File "C:\Python37\lib\site-packages\discord\ext\commands\core.py", line 79, in wrapped\n    ret = await coro(*args, **kwargs)\n  File "C:\Users\Vyryn\PycharmProjects\davidbot\cogs\corp.py", line 369, in list_rsi_links\n    if channel.members.length() < 1:\nAttributeError: 'list' object has no attribute 'length'\n\nThe above exception was the direct cause of the following exception:\n\nTraceback (most recent call last):\n  File "C:\Python37\lib\site-packages\discord\ext\commands\bot.py", line 863, in invoke\n    await ctx.command.invoke(ctx)\n  File "C:\Python37\lib\site-packages\discord\ext\commands\core.py", line 728, in invoke\n    await injected(*ctx.args, **ctx.kwargs)\n  File "C:\Python37\lib\site-packages\discord\ext\commands\core.py", line 88, in wrapped\n    raise CommandInvokeError(exc) from exc\ndiscord.ext.commands.errors.CommandInvokeError: Command raised an exception: AttributeError: 'list' object has no attribute 'length'\n\n```
Message logged at 01/24/20 23:31:34 by Bot David8#4665 in Channel Direct Message with Vyryn#4618: with Content: ```py\nTraceback (most recent call last):\n  File "C:\Python37\lib\site-packages\discord\ext\commands\core.py", line 79, in wrapped\n    ret = await coro(*args, **kwargs)\n  File "C:\Users\Vyryn\PycharmProjects\davidbot\cogs\corp.py", line 369, in list_rsi_links\n    if channel.members.length() < 1:\nAttributeError: 'list' object has no attribute 'length'\n\nThe above exception was the direct cause of the following exception:\n\nTraceback (most recent call last):\n  File "C:\Python37\lib\site-packages\discord\ext\commands\bot.py", line 863, in invoke\n    await ctx.command.invoke(ctx)\n  File "C:\Python37\lib\site-packages\discord\ext\commands\core.py", line 728, in invoke\n    await injected(*ctx.args, **ctx.kwargs)\n  File "C:\Python37\lib\site-packages\discord\ext\commands\core.py", line 88, in wrapped\n    raise CommandInvokeError(exc) from exc\ndiscord.ext.commands.errors.CommandInvokeError: Command raised an exception: AttributeError: 'list' object has no attribute 'length'\n\n```
Message logged at 01/24/20 23:32:31 by Bot David8#4665 in Channel Direct Message with Vyryn#4618: with Content: ```py\nTraceback (most recent call last):\n  File "C:\Python37\lib\site-packages\discord\ext\commands\core.py", line 79, in wrapped\n    ret = await coro(*args, **kwargs)\n  File "C:\Users\Vyryn\PycharmProjects\davidbot\cogs\corp.py", line 369, in list_rsi_links\n    if len(channel.members) < 1:\nAttributeError: 'str' object has no attribute 'members'\n\nThe above exception was the direct cause of the following exception:\n\nTraceback (most recent call last):\n  File "C:\Python37\lib\site-packages\discord\ext\commands\bot.py", line 863, in invoke\n    await ctx.command.invoke(ctx)\n  File "C:\Python37\lib\site-packages\discord\ext\commands\core.py", line 728, in invoke\n    await injected(*ctx.args, **ctx.kwargs)\n  File "C:\Python37\lib\site-packages\discord\ext\commands\core.py", line 88, in wrapped\n    raise CommandInvokeError(exc) from exc\ndiscord.ext.commands.errors.CommandInvokeError: Command raised an exception: AttributeError: 'str' object has no attribute 'members'\n\n```
Message logged at 01/24/20 23:32:42 by Bot David8#4665 in Channel Direct Message with Vyryn#4618: with Content: ```py\nTraceback (most recent call last):\n  File "C:\Python37\lib\site-packages\discord\ext\commands\core.py", line 79, in wrapped\n    ret = await coro(*args, **kwargs)\n  File "C:\Users\Vyryn\PycharmProjects\davidbot\cogs\corp.py", line 369, in list_rsi_links\n    if len(channel.members) < 1:\nAttributeError: 'str' object has no attribute 'members'\n\nThe above exception was the direct cause of the following exception:\n\nTraceback (most recent call last):\n  File "C:\Python37\lib\site-packages\discord\ext\commands\bot.py", line 863, in invoke\n    await ctx.command.invoke(ctx)\n  File "C:\Python37\lib\site-packages\discord\ext\commands\core.py", line 728, in invoke\n    await injected(*ctx.args, **ctx.kwargs)\n  File "C:\Python37\lib\site-packages\discord\ext\commands\core.py", line 88, in wrapped\n    raise CommandInvokeError(exc) from exc\ndiscord.ext.commands.errors.CommandInvokeError: Command raised an exception: AttributeError: 'str' object has no attribute 'members'\n\n```
Message logged at 01/25/20 03:40:39 by Bot David8#4665 in Channel Direct Message with Vyryn#4618: with Content: ```py\nTraceback (most recent call last):\n  File "C:\Python37\lib\site-packages\discord\ext\commands\bot.py", line 863, in invoke\n    await ctx.command.invoke(ctx)\n  File "C:\Python37\lib\site-packages\discord\ext\commands\core.py", line 721, in invoke\n    await self.prepare(ctx)\n  File "C:\Python37\lib\site-packages\discord\ext\commands\core.py", line 685, in prepare\n    await self._parse_arguments(ctx)\n  File "C:\Python37\lib\site-packages\discord\ext\commands\core.py", line 599, in _parse_arguments\n    transformed = await self.transform(ctx, param)\n  File "C:\Python37\lib\site-packages\discord\ext\commands\core.py", line 455, in transform\n    return await self.do_conversion(ctx, converter, argument, param)\n  File "C:\Python37\lib\site-packages\discord\ext\commands\core.py", line 408, in do_conversion\n    return await self._actual_conversion(ctx, converter, argument, param)\n  File "C:\Python37\lib\site-packages\discord\ext\commands\core.py", line 354, in _actual_conversion\n    ret = await instance.convert(ctx, argument)\n  File "C:\Python37\lib\site-packages\discord\ext\commands\converter.py", line 171, in convert\n    raise BadArgument('User "{}" not found'.format(argument))\ndiscord.ext.commands.errors.BadArgument: User "1" not found\n\n```
Message logged at 01/25/20 03:40:47 by Bot David8#4665 in Channel Direct Message with Vyryn#4618: with Content: ```py\nTraceback (most recent call last):\n  File "C:\Python37\lib\site-packages\discord\ext\commands\core.py", line 79, in wrapped\n    ret = await coro(*args, **kwargs)\n  File "C:\Users\Vyryn\PycharmProjects\davidbot\cogs\dev.py", line 103, in authset\n    with open('../auths.json', 'r') as f:\nFileNotFoundError: [Errno 2] No such file or directory: '../auths.json'\n\nThe above exception was the direct cause of the following exception:\n\nTraceback (most recent call last):\n  File "C:\Python37\lib\site-packages\discord\ext\commands\bot.py", line 863, in invoke\n    await ctx.command.invoke(ctx)\n  File "C:\Python37\lib\site-packages\discord\ext\commands\core.py", line 728, in invoke\n    await injected(*ctx.args, **ctx.kwargs)\n  File "C:\Python37\lib\site-packages\discord\ext\commands\core.py", line 88, in wrapped\n    raise CommandInvokeError(exc) from exc\ndiscord.ext.commands.errors.CommandInvokeError: Command raised an exception: FileNotFoundError: [Errno 2] No such file or directory: '../auths.json'\n\n```
Message logged at 01/25/20 03:43:00 by Bot David8#4665 in Channel Direct Message with Vyryn#4618: with Content: ```py\nTraceback (most recent call last):\n  File "C:\Python37\lib\site-packages\discord\ext\commands\core.py", line 79, in wrapped\n    ret = await coro(*args, **kwargs)\n  File "C:\Users\Vyryn\PycharmProjects\davidbot\cogs\dev.py", line 103, in authset\n    with open('../auths.json', 'r') as f:\nFileNotFoundError: [Errno 2] No such file or directory: '../auths.json'\n\nThe above exception was the direct cause of the following exception:\n\nTraceback (most recent call last):\n  File "C:\Python37\lib\site-packages\discord\ext\commands\bot.py", line 863, in invoke\n    await ctx.command.invoke(ctx)\n  File "C:\Python37\lib\site-packages\discord\ext\commands\core.py", line 728, in invoke\n    await injected(*ctx.args, **ctx.kwargs)\n  File "C:\Python37\lib\site-packages\discord\ext\commands\core.py", line 88, in wrapped\n    raise CommandInvokeError(exc) from exc\ndiscord.ext.commands.errors.CommandInvokeError: Command raised an exception: FileNotFoundError: [Errno 2] No such file or directory: '../auths.json'\n\n```
Message logged at 01/25/20 03:43:57 by Bot David8#4665 in Channel Direct Message with Vyryn#4618: with Content: ```py\nTraceback (most recent call last):\n  File "C:\Python37\lib\site-packages\discord\ext\commands\bot.py", line 863, in invoke\n    await ctx.command.invoke(ctx)\n  File "C:\Python37\lib\site-packages\discord\ext\commands\core.py", line 721, in invoke\n    await self.prepare(ctx)\n  File "C:\Python37\lib\site-packages\discord\ext\commands\core.py", line 685, in prepare\n    await self._parse_arguments(ctx)\n  File "C:\Python37\lib\site-packages\discord\ext\commands\core.py", line 599, in _parse_arguments\n    transformed = await self.transform(ctx, param)\n  File "C:\Python37\lib\site-packages\discord\ext\commands\core.py", line 455, in transform\n    return await self.do_conversion(ctx, converter, argument, param)\n  File "C:\Python37\lib\site-packages\discord\ext\commands\core.py", line 408, in do_conversion\n    return await self._actual_conversion(ctx, converter, argument, param)\n  File "C:\Python37\lib\site-packages\discord\ext\commands\core.py", line 354, in _actual_conversion\n    ret = await instance.convert(ctx, argument)\n  File "C:\Python37\lib\site-packages\discord\ext\commands\converter.py", line 171, in convert\n    raise BadArgument('User "{}" not found'.format(argument))\ndiscord.ext.commands.errors.BadArgument: User "4" not found\n\n```
Message logged at 01/25/20 03:44:44 by Bot David8#4665 in Channel Direct Message with Vyryn#4618: with Content: ```py\nTraceback (most recent call last):\n  File "C:\Python37\lib\site-packages\discord\ext\commands\core.py", line 79, in wrapped\n    ret = await coro(*args, **kwargs)\n  File "C:\Users\Vyryn\PycharmProjects\davidbot\cogs\dev.py", line 73, in autho\n    print(f'Auth command used by {ctx.author} at {now()}')\nOSError: [Errno 22] Invalid argument\n\nThe above exception was the direct cause of the following exception:\n\nTraceback (most recent call last):\n  File "C:\Python37\lib\site-packages\discord\ext\commands\bot.py", line 863, in invoke\n    await ctx.command.invoke(ctx)\n  File "C:\Python37\lib\site-packages\discord\ext\commands\core.py", line 1154, in invoke\n    await injected(*ctx.args, **ctx.kwargs)\n  File "C:\Python37\lib\site-packages\discord\ext\commands\core.py", line 88, in wrapped\n    raise CommandInvokeError(exc) from exc\ndiscord.ext.commands.errors.CommandInvokeError: Command raised an exception: OSError: [Errno 22] Invalid argument\n\n```
Message logged at 01/25/20 03:44:50 by Bot David8#4665 in Channel Direct Message with Vyryn#4618: with Content: ```py\nTraceback (most recent call last):\n  File "C:\Python37\lib\site-packages\discord\ext\commands\core.py", line 79, in wrapped\n    ret = await coro(*args, **kwargs)\n  File "C:\Users\Vyryn\PycharmProjects\davidbot\cogs\dev.py", line 73, in autho\n    print(f'Auth command used by {ctx.author} at {now()}')\nOSError: [Errno 22] Invalid argument\n\nThe above exception was the direct cause of the following exception:\n\nTraceback (most recent call last):\n  File "C:\Python37\lib\site-packages\discord\ext\commands\bot.py", line 863, in invoke\n    await ctx.command.invoke(ctx)\n  File "C:\Python37\lib\site-packages\discord\ext\commands\core.py", line 1154, in invoke\n    await injected(*ctx.args, **ctx.kwargs)\n  File "C:\Python37\lib\site-packages\discord\ext\commands\core.py", line 88, in wrapped\n    raise CommandInvokeError(exc) from exc\ndiscord.ext.commands.errors.CommandInvokeError: Command raised an exception: OSError: [Errno 22] Invalid argument\n\n```
Message logged at 01/25/20 03:44:55 by Bot David8#4665 in Channel Direct Message with Vyryn#4618: with Content: ```py\nTraceback (most recent call last):\n  File "C:\Python37\lib\site-packages\discord\ext\commands\core.py", line 79, in wrapped\n    ret = await coro(*args, **kwargs)\n  File "C:\Users\Vyryn\PycharmProjects\davidbot\cogs\dev.py", line 73, in autho\n    print(f'Auth command used by {ctx.author} at {now()}')\nOSError: [Errno 22] Invalid argument\n\nThe above exception was the direct cause of the following exception:\n\nTraceback (most recent call last):\n  File "C:\Python37\lib\site-packages\discord\ext\commands\bot.py", line 863, in invoke\n    await ctx.command.invoke(ctx)\n  File "C:\Python37\lib\site-packages\discord\ext\commands\core.py", line 1154, in invoke\n    await injected(*ctx.args, **ctx.kwargs)\n  File "C:\Python37\lib\site-packages\discord\ext\commands\core.py", line 88, in wrapped\n    raise CommandInvokeError(exc) from exc\ndiscord.ext.commands.errors.CommandInvokeError: Command raised an exception: OSError: [Errno 22] Invalid argument\n\n```
Message logged at 01/25/20 03:45:24 by Bot David8#4665 in Channel <Object id=670476444501016586>: with Content: ```py\nTraceback (most recent call last):\n  File "C:\Python37\lib\site-packages\discord\ext\commands\core.py", line 79, in wrapped\n    ret = await coro(*args, **kwargs)\n  File "C:\Users\Vyryn\PycharmProjects\davidbot\cogs\dev.py", line 73, in autho\n    print(f'Auth command used by {ctx.author} at {now()}')\nOSError: [Errno 22] Invalid argument\n\nThe above exception was the direct cause of the following exception:\n\nTraceback (most recent call last):\n  File "C:\Python37\lib\site-packages\discord\ext\commands\bot.py", line 863, in invoke\n    await ctx.command.invoke(ctx)\n  File "C:\Python37\lib\site-packages\discord\ext\commands\core.py", line 1154, in invoke\n    await injected(*ctx.args, **ctx.kwargs)\n  File "C:\Python37\lib\site-packages\discord\ext\commands\core.py", line 88, in wrapped\n    raise CommandInvokeError(exc) from exc\ndiscord.ext.commands.errors.CommandInvokeError: Command raised an exception: OSError: [Errno 22] Invalid argument\n\n```
Message logged at 01/25/20 03:45:24 by Bot David8#4665 in Channel Direct Message with Vyryn#4618: with Content: ```py\nTraceback (most recent call last):\n  File "C:\Python37\lib\site-packages\discord\ext\commands\core.py", line 79, in wrapped\n    ret = await coro(*args, **kwargs)\n  File "C:\Users\Vyryn\PycharmProjects\davidbot\cogs\dev.py", line 73, in autho\n    print(f'Auth command used by {ctx.author} at {now()}')\nOSError: [Errno 22] Invalid argument\n\nThe above exception was the direct cause of the following exception:\n\nTraceback (most recent call last):\n  File "C:\Python37\lib\site-packages\discord\ext\commands\bot.py", line 863, in invoke\n    await ctx.command.invoke(ctx)\n  File "C:\Python37\lib\site-packages\discord\ext\commands\core.py", line 1154, in invoke\n    await injected(*ctx.args, **ctx.kwargs)\n  File "C:\Python37\lib\site-packages\discord\ext\commands\core.py", line 88, in wrapped\n    raise CommandInvokeError(exc) from exc\ndiscord.ext.commands.errors.CommandInvokeError: Command raised an exception: OSError: [Errno 22] Invalid argument\n\n```
Message logged at 01/25/20 04:29:41 by Bot David8#4665 in Channel Direct Message with Vyryn#4618: with Content: ```py\nTraceback (most recent call last):\n  File "C:\Python37\lib\site-packages\discord\ext\commands\core.py", line 79, in wrapped\n    ret = await coro(*args, **kwargs)\n  File "C:\Users\Vyryn\PycharmProjects\davidbot\cogs\corp.py", line 391, in reqdiv\n    print(divs_list)\nOSError: [Errno 22] Invalid argument\n\nThe above exception was the direct cause of the following exception:\n\nTraceback (most recent call last):\n  File "C:\Python37\lib\site-packages\discord\ext\commands\bot.py", line 863, in invoke\n    await ctx.command.invoke(ctx)\n  File "C:\Python37\lib\site-packages\discord\ext\commands\core.py", line 728, in invoke\n    await injected(*ctx.args, **ctx.kwargs)\n  File "C:\Python37\lib\site-packages\discord\ext\commands\core.py", line 88, in wrapped\n    raise CommandInvokeError(exc) from exc\ndiscord.ext.commands.errors.CommandInvokeError: Command raised an exception: OSError: [Errno 22] Invalid argument\n\n```
Message logged at 01/25/20 04:30:13 by Bot David8#4665 in Channel Direct Message with Vyryn#4618: with Content: ```py\nTraceback (most recent call last):\n  File "C:\Python37\lib\site-packages\discord\ext\commands\core.py", line 79, in wrapped\n    ret = await coro(*args, **kwargs)\n  File "C:\Users\Vyryn\PycharmProjects\davidbot\cogs\corp.py", line 391, in reqdiv\n    print(divs_list)\nOSError: [Errno 22] Invalid argument\n\nThe above exception was the direct cause of the following exception:\n\nTraceback (most recent call last):\n  File "C:\Python37\lib\site-packages\discord\ext\commands\bot.py", line 863, in invoke\n    await ctx.command.invoke(ctx)\n  File "C:\Python37\lib\site-packages\discord\ext\commands\core.py", line 728, in invoke\n    await injected(*ctx.args, **ctx.kwargs)\n  File "C:\Python37\lib\site-packages\discord\ext\commands\core.py", line 88, in wrapped\n    raise CommandInvokeError(exc) from exc\ndiscord.ext.commands.errors.CommandInvokeError: Command raised an exception: OSError: [Errno 22] Invalid argument\n\n```
Message logged at 01/25/20 04:30:13 by Bot David8#4665 in Channel Direct Message with Vyryn#4618: with Content: ```py\nTraceback (most recent call last):\n  File "C:\Python37\lib\site-packages\discord\ext\commands\core.py", line 79, in wrapped\n    ret = await coro(*args, **kwargs)\n  File "C:\Users\Vyryn\PycharmProjects\davidbot\cogs\corp.py", line 391, in reqdiv\n    print(divs_list)\nOSError: [Errno 22] Invalid argument\n\nThe above exception was the direct cause of the following exception:\n\nTraceback (most recent call last):\n  File "C:\Python37\lib\site-packages\discord\ext\commands\bot.py", line 863, in invoke\n    await ctx.command.invoke(ctx)\n  File "C:\Python37\lib\site-packages\discord\ext\commands\core.py", line 728, in invoke\n    await injected(*ctx.args, **ctx.kwargs)\n  File "C:\Python37\lib\site-packages\discord\ext\commands\core.py", line 88, in wrapped\n    raise CommandInvokeError(exc) from exc\ndiscord.ext.commands.errors.CommandInvokeError: Command raised an exception: OSError: [Errno 22] Invalid argument\n\n```
Message logged at 01/25/20 04:30:26 by Bot David8#4665 in Channel Direct Message with Vyryn#4618: with Content: ```py\nTraceback (most recent call last):\n  File "C:\Python37\lib\site-packages\discord\ext\commands\core.py", line 79, in wrapped\n    ret = await coro(*args, **kwargs)\n  File "C:\Users\Vyryn\PycharmProjects\davidbot\cogs\corp.py", line 391, in reqdiv\n    print(divs_list)\nOSError: [Errno 22] Invalid argument\n\nThe above exception was the direct cause of the following exception:\n\nTraceback (most recent call last):\n  File "C:\Python37\lib\site-packages\discord\ext\commands\bot.py", line 863, in invoke\n    await ctx.command.invoke(ctx)\n  File "C:\Python37\lib\site-packages\discord\ext\commands\core.py", line 728, in invoke\n    await injected(*ctx.args, **ctx.kwargs)\n  File "C:\Python37\lib\site-packages\discord\ext\commands\core.py", line 88, in wrapped\n    raise CommandInvokeError(exc) from exc\ndiscord.ext.commands.errors.CommandInvokeError: Command raised an exception: OSError: [Errno 22] Invalid argument\n\n```
Message logged at 01/25/20 04:30:26 by Bot David8#4665 in Channel Direct Message with Vyryn#4618: with Content: ```py\nTraceback (most recent call last):\n  File "C:\Python37\lib\site-packages\discord\ext\commands\core.py", line 79, in wrapped\n    ret = await coro(*args, **kwargs)\n  File "C:\Users\Vyryn\PycharmProjects\davidbot\cogs\corp.py", line 391, in reqdiv\n    print(divs_list)\nOSError: [Errno 22] Invalid argument\n\nThe above exception was the direct cause of the following exception:\n\nTraceback (most recent call last):\n  File "C:\Python37\lib\site-packages\discord\ext\commands\bot.py", line 863, in invoke\n    await ctx.command.invoke(ctx)\n  File "C:\Python37\lib\site-packages\discord\ext\commands\core.py", line 728, in invoke\n    await injected(*ctx.args, **ctx.kwargs)\n  File "C:\Python37\lib\site-packages\discord\ext\commands\core.py", line 88, in wrapped\n    raise CommandInvokeError(exc) from exc\ndiscord.ext.commands.errors.CommandInvokeError: Command raised an exception: OSError: [Errno 22] Invalid argument\n\n```
Message logged at 01/25/20 04:30:47 by Bot David8#4665 in Channel Direct Message with Vyryn#4618: with Content: ```py\nTraceback (most recent call last):\n  File "C:\Python37\lib\site-packages\discord\ext\commands\core.py", line 79, in wrapped\n    ret = await coro(*args, **kwargs)\n  File "C:\Users\Vyryn\PycharmProjects\davidbot\cogs\corp.py", line 391, in reqdiv\n    print(divs_list)\nOSError: [Errno 22] Invalid argument\n\nThe above exception was the direct cause of the following exception:\n\nTraceback (most recent call last):\n  File "C:\Python37\lib\site-packages\discord\ext\commands\bot.py", line 863, in invoke\n    await ctx.command.invoke(ctx)\n  File "C:\Python37\lib\site-packages\discord\ext\commands\core.py", line 728, in invoke\n    await injected(*ctx.args, **ctx.kwargs)\n  File "C:\Python37\lib\site-packages\discord\ext\commands\core.py", line 88, in wrapped\n    raise CommandInvokeError(exc) from exc\ndiscord.ext.commands.errors.CommandInvokeError: Command raised an exception: OSError: [Errno 22] Invalid argument\n\n```
Message logged at 01/25/20 04:30:47 by Bot David8#4665 in Channel Direct Message with Vyryn#4618: with Content: ```py\nTraceback (most recent call last):\n  File "C:\Python37\lib\site-packages\discord\ext\commands\core.py", line 79, in wrapped\n    ret = await coro(*args, **kwargs)\n  File "C:\Users\Vyryn\PycharmProjects\davidbot\cogs\corp.py", line 391, in reqdiv\n    print(divs_list)\nOSError: [Errno 22] Invalid argument\n\nThe above exception was the direct cause of the following exception:\n\nTraceback (most recent call last):\n  File "C:\Python37\lib\site-packages\discord\ext\commands\bot.py", line 863, in invoke\n    await ctx.command.invoke(ctx)\n  File "C:\Python37\lib\site-packages\discord\ext\commands\core.py", line 728, in invoke\n    await injected(*ctx.args, **ctx.kwargs)\n  File "C:\Python37\lib\site-packages\discord\ext\commands\core.py", line 88, in wrapped\n    raise CommandInvokeError(exc) from exc\ndiscord.ext.commands.errors.CommandInvokeError: Command raised an exception: OSError: [Errno 22] Invalid argument\n\n```
Message logged at 01/25/20 04:31:28 by Bot David8#4665 in Channel Direct Message with Vyryn#4618: with Content: ```py\nTraceback (most recent call last):\n  File "C:\Python37\lib\site-packages\discord\ext\commands\core.py", line 79, in wrapped\n    ret = await coro(*args, **kwargs)\n  File "C:\Users\Vyryn\PycharmProjects\davidbot\cogs\corp.py", line 391, in reqdiv\n    print(divs_list)\nOSError: [Errno 22] Invalid argument\n\nThe above exception was the direct cause of the following exception:\n\nTraceback (most recent call last):\n  File "C:\Python37\lib\site-packages\discord\ext\commands\bot.py", line 863, in invoke\n    await ctx.command.invoke(ctx)\n  File "C:\Python37\lib\site-packages\discord\ext\commands\core.py", line 728, in invoke\n    await injected(*ctx.args, **ctx.kwargs)\n  File "C:\Python37\lib\site-packages\discord\ext\commands\core.py", line 88, in wrapped\n    raise CommandInvokeError(exc) from exc\ndiscord.ext.commands.errors.CommandInvokeError: Command raised an exception: OSError: [Errno 22] Invalid argument\n\n```
Message logged at 01/25/20 04:31:28 by Bot David8#4665 in Channel Direct Message with Vyryn#4618: with Content: ```py\nTraceback (most recent call last):\n  File "C:\Python37\lib\site-packages\discord\ext\commands\core.py", line 79, in wrapped\n    ret = await coro(*args, **kwargs)\n  File "C:\Users\Vyryn\PycharmProjects\davidbot\cogs\corp.py", line 391, in reqdiv\n    print(divs_list)\nOSError: [Errno 22] Invalid argument\n\nThe above exception was the direct cause of the following exception:\n\nTraceback (most recent call last):\n  File "C:\Python37\lib\site-packages\discord\ext\commands\bot.py", line 863, in invoke\n    await ctx.command.invoke(ctx)\n  File "C:\Python37\lib\site-packages\discord\ext\commands\core.py", line 728, in invoke\n    await injected(*ctx.args, **ctx.kwargs)\n  File "C:\Python37\lib\site-packages\discord\ext\commands\core.py", line 88, in wrapped\n    raise CommandInvokeError(exc) from exc\ndiscord.ext.commands.errors.CommandInvokeError: Command raised an exception: OSError: [Errno 22] Invalid argument\n\n```
Message logged at 01/25/20 04:32:09 by Bot David8#4665 in Channel Direct Message with Vyryn#4618: with Content: ```py\nTraceback (most recent call last):\n  File "C:\Python37\lib\site-packages\discord\ext\commands\core.py", line 79, in wrapped\n    ret = await coro(*args, **kwargs)\n  File "C:\Users\Vyryn\PycharmProjects\davidbot\cogs\corp.py", line 391, in reqdiv\n    print(divs_list)\nOSError: [Errno 22] Invalid argument\n\nThe above exception was the direct cause of the following exception:\n\nTraceback (most recent call last):\n  File "C:\Python37\lib\site-packages\discord\ext\commands\bot.py", line 863, in invoke\n    await ctx.command.invoke(ctx)\n  File "C:\Python37\lib\site-packages\discord\ext\commands\core.py", line 728, in invoke\n    await injected(*ctx.args, **ctx.kwargs)\n  File "C:\Python37\lib\site-packages\discord\ext\commands\core.py", line 88, in wrapped\n    raise CommandInvokeError(exc) from exc\ndiscord.ext.commands.errors.CommandInvokeError: Command raised an exception: OSError: [Errno 22] Invalid argument\n\n```
Message logged at 01/25/20 04:32:48 by Bot David8#4665 in Channel Direct Message with Vyryn#4618: with Content: ```py\nTraceback (most recent call last):\n  File "C:\Python37\lib\site-packages\discord\ext\commands\core.py", line 79, in wrapped\n    ret = await coro(*args, **kwargs)\n  File "C:\Users\Vyryn\PycharmProjects\davidbot\cogs\corp.py", line 391, in reqdiv\n    print(divs_list)\nOSError: [Errno 22] Invalid argument\n\nThe above exception was the direct cause of the following exception:\n\nTraceback (most recent call last):\n  File "C:\Python37\lib\site-packages\discord\ext\commands\bot.py", line 863, in invoke\n    await ctx.command.invoke(ctx)\n  File "C:\Python37\lib\site-packages\discord\ext\commands\core.py", line 728, in invoke\n    await injected(*ctx.args, **ctx.kwargs)\n  File "C:\Python37\lib\site-packages\discord\ext\commands\core.py", line 88, in wrapped\n    raise CommandInvokeError(exc) from exc\ndiscord.ext.commands.errors.CommandInvokeError: Command raised an exception: OSError: [Errno 22] Invalid argument\n\n```
Message logged at 01/25/20 13:14:12 by Bot David8#4665 in Channel Direct Message with Vyryn#4618: with Content: ```py\nTraceback (most recent call last):\n  File "C:\Python37\lib\site-packages\discord\ext\commands\core.py", line 79, in wrapped\n    ret = await coro(*args, **kwargs)\n  File "C:\Users\Vyryn\PycharmProjects\davidbot\cogs\corp.py", line 391, in reqdiv\n    print(divs_list)\nOSError: [Errno 22] Invalid argument\n\nThe above exception was the direct cause of the following exception:\n\nTraceback (most recent call last):\n  File "C:\Python37\lib\site-packages\discord\ext\commands\bot.py", line 863, in invoke\n    await ctx.command.invoke(ctx)\n  File "C:\Python37\lib\site-packages\discord\ext\commands\core.py", line 728, in invoke\n    await injected(*ctx.args, **ctx.kwargs)\n  File "C:\Python37\lib\site-packages\discord\ext\commands\core.py", line 88, in wrapped\n    raise CommandInvokeError(exc) from exc\ndiscord.ext.commands.errors.CommandInvokeError: Command raised an exception: OSError: [Errno 22] Invalid argument\n\n```
Message logged at 01/25/20 13:14:12 by Bot David8#4665 in Channel Direct Message with Vyryn#4618: with Content: ```py\nTraceback (most recent call last):\n  File "C:\Python37\lib\site-packages\discord\ext\commands\core.py", line 79, in wrapped\n    ret = await coro(*args, **kwargs)\n  File "C:\Users\Vyryn\PycharmProjects\davidbot\cogs\corp.py", line 391, in reqdiv\n    print(divs_list)\nOSError: [Errno 22] Invalid argument\n\nThe above exception was the direct cause of the following exception:\n\nTraceback (most recent call last):\n  File "C:\Python37\lib\site-packages\discord\ext\commands\bot.py", line 863, in invoke\n    await ctx.command.invoke(ctx)\n  File "C:\Python37\lib\site-packages\discord\ext\commands\core.py", line 728, in invoke\n    await injected(*ctx.args, **ctx.kwargs)\n  File "C:\Python37\lib\site-packages\discord\ext\commands\core.py", line 88, in wrapped\n    raise CommandInvokeError(exc) from exc\ndiscord.ext.commands.errors.CommandInvokeError: Command raised an exception: OSError: [Errno 22] Invalid argument\n\n```
Message logged at 01/25/20 13:14:48 by Bot David8#4665 in Channel Direct Message with Vyryn#4618: with Content: ```py\nTraceback (most recent call last):\n  File "C:\Python37\lib\site-packages\discord\ext\commands\core.py", line 79, in wrapped\n    ret = await coro(*args, **kwargs)\n  File "C:\Users\Vyryn\PycharmProjects\davidbot\cogs\corp.py", line 391, in reqdiv\n    print(divs_list)\nOSError: [Errno 22] Invalid argument\n\nThe above exception was the direct cause of the following exception:\n\nTraceback (most recent call last):\n  File "C:\Python37\lib\site-packages\discord\ext\commands\bot.py", line 863, in invoke\n    await ctx.command.invoke(ctx)\n  File "C:\Python37\lib\site-packages\discord\ext\commands\core.py", line 728, in invoke\n    await injected(*ctx.args, **ctx.kwargs)\n  File "C:\Python37\lib\site-packages\discord\ext\commands\core.py", line 88, in wrapped\n    raise CommandInvokeError(exc) from exc\ndiscord.ext.commands.errors.CommandInvokeError: Command raised an exception: OSError: [Errno 22] Invalid argument\n\n```
Message logged at 01/25/20 13:14:48 by Bot David8#4665 in Channel Direct Message with Vyryn#4618: with Content: ```py\nTraceback (most recent call last):\n  File "C:\Python37\lib\site-packages\discord\ext\commands\core.py", line 79, in wrapped\n    ret = await coro(*args, **kwargs)\n  File "C:\Users\Vyryn\PycharmProjects\davidbot\cogs\corp.py", line 391, in reqdiv\n    print(divs_list)\nOSError: [Errno 22] Invalid argument\n\nThe above exception was the direct cause of the following exception:\n\nTraceback (most recent call last):\n  File "C:\Python37\lib\site-packages\discord\ext\commands\bot.py", line 863, in invoke\n    await ctx.command.invoke(ctx)\n  File "C:\Python37\lib\site-packages\discord\ext\commands\core.py", line 728, in invoke\n    await injected(*ctx.args, **ctx.kwargs)\n  File "C:\Python37\lib\site-packages\discord\ext\commands\core.py", line 88, in wrapped\n    raise CommandInvokeError(exc) from exc\ndiscord.ext.commands.errors.CommandInvokeError: Command raised an exception: OSError: [Errno 22] Invalid argument\n\n```
Message logged at 01/25/20 14:05:59 by Bot David8#4665 in Channel Direct Message with Vyryn#4618: with Content: ```py\nTraceback (most recent call last):\n  File "C:\Python37\lib\site-packages\discord\ext\commands\core.py", line 79, in wrapped\n    ret = await coro(*args, **kwargs)\n  File "C:\Users\Vyryn\PycharmProjects\davidbot\cogs\corp.py", line 391, in reqdiv\n    print(divs_list)\nOSError: [Errno 22] Invalid argument\n\nThe above exception was the direct cause of the following exception:\n\nTraceback (most recent call last):\n  File "C:\Python37\lib\site-packages\discord\ext\commands\bot.py", line 863, in invoke\n    await ctx.command.invoke(ctx)\n  File "C:\Python37\lib\site-packages\discord\ext\commands\core.py", line 728, in invoke\n    await injected(*ctx.args, **ctx.kwargs)\n  File "C:\Python37\lib\site-packages\discord\ext\commands\core.py", line 88, in wrapped\n    raise CommandInvokeError(exc) from exc\ndiscord.ext.commands.errors.CommandInvokeError: Command raised an exception: OSError: [Errno 22] Invalid argument\n\n```
Message logged at 01/25/20 14:07:05 by Bot David8#4665 in Channel Direct Message with Vyryn#4618: with Content: ```py\nTraceback (most recent call last):\n  File "C:\Python37\lib\site-packages\discord\ext\commands\core.py", line 79, in wrapped\n    ret = await coro(*args, **kwargs)\n  File "C:\Users\Vyryn\PycharmProjects\davidbot\cogs\moderation.py", line 44, in purge\n    return print(f'{ctx.author} deleted {amount} messages in channel {ctx.channel} in guild {ctx.guild}.')\nOSError: [Errno 22] Invalid argument\n\nThe above exception was the direct cause of the following exception:\n\nTraceback (most recent call last):\n  File "C:\Python37\lib\site-packages\discord\ext\commands\bot.py", line 863, in invoke\n    await ctx.command.invoke(ctx)\n  File "C:\Python37\lib\site-packages\discord\ext\commands\core.py", line 728, in invoke\n    await injected(*ctx.args, **ctx.kwargs)\n  File "C:\Python37\lib\site-packages\discord\ext\commands\core.py", line 88, in wrapped\n    raise CommandInvokeError(exc) from exc\ndiscord.ext.commands.errors.CommandInvokeError: Command raised an exception: OSError: [Errno 22] Invalid argument\n\n```
Message logged at 01/25/20 14:07:05 by Bot David8#4665 in Channel Direct Message with Vyryn#4618: with Content: ```py\nTraceback (most recent call last):\n  File "C:\Python37\lib\site-packages\discord\ext\commands\core.py", line 79, in wrapped\n    ret = await coro(*args, **kwargs)\n  File "C:\Users\Vyryn\PycharmProjects\davidbot\cogs\moderation.py", line 44, in purge\n    return print(f'{ctx.author} deleted {amount} messages in channel {ctx.channel} in guild {ctx.guild}.')\nOSError: [Errno 22] Invalid argument\n\nThe above exception was the direct cause of the following exception:\n\nTraceback (most recent call last):\n  File "C:\Python37\lib\site-packages\discord\ext\commands\bot.py", line 863, in invoke\n    await ctx.command.invoke(ctx)\n  File "C:\Python37\lib\site-packages\discord\ext\commands\core.py", line 728, in invoke\n    await injected(*ctx.args, **ctx.kwargs)\n  File "C:\Python37\lib\site-packages\discord\ext\commands\core.py", line 88, in wrapped\n    raise CommandInvokeError(exc) from exc\ndiscord.ext.commands.errors.CommandInvokeError: Command raised an exception: OSError: [Errno 22] Invalid argument\n\n```
Message logged at 01/25/20 14:09:26 by Bot David8#4665 in Channel Direct Message with Vyryn#4618: with Content: ```py\nTraceback (most recent call last):\n  File "C:\Python37\lib\site-packages\discord\ext\commands\core.py", line 79, in wrapped\n    ret = await coro(*args, **kwargs)\n  File "C:\Users\Vyryn\PycharmProjects\davidbot\cogs\corp.py", line 397, in reqdiv\n    print(f'{role.casefold()} vs DL {div}')\nAttributeError: 'Role' object has no attribute 'casefold'\n\nThe above exception was the direct cause of the following exception:\n\nTraceback (most recent call last):\n  File "C:\Python37\lib\site-packages\discord\ext\commands\bot.py", line 863, in invoke\n    await ctx.command.invoke(ctx)\n  File "C:\Python37\lib\site-packages\discord\ext\commands\core.py", line 728, in invoke\n    await injected(*ctx.args, **ctx.kwargs)\n  File "C:\Python37\lib\site-packages\discord\ext\commands\core.py", line 88, in wrapped\n    raise CommandInvokeError(exc) from exc\ndiscord.ext.commands.errors.CommandInvokeError: Command raised an exception: AttributeError: 'Role' object has no attribute 'casefold'\n\n```
Message logged at 01/25/20 14:09:26 by Bot David8#4665 in Channel Direct Message with Vyryn#4618: with Content: ```py\nTraceback (most recent call last):\n  File "C:\Python37\lib\site-packages\discord\ext\commands\core.py", line 79, in wrapped\n    ret = await coro(*args, **kwargs)\n  File "C:\Users\Vyryn\PycharmProjects\davidbot\cogs\corp.py", line 397, in reqdiv\n    print(f'{role.casefold()} vs DL {div}')\nAttributeError: 'Role' object has no attribute 'casefold'\n\nThe above exception was the direct cause of the following exception:\n\nTraceback (most recent call last):\n  File "C:\Python37\lib\site-packages\discord\ext\commands\bot.py", line 863, in invoke\n    await ctx.command.invoke(ctx)\n  File "C:\Python37\lib\site-packages\discord\ext\commands\core.py", line 728, in invoke\n    await injected(*ctx.args, **ctx.kwargs)\n  File "C:\Python37\lib\site-packages\discord\ext\commands\core.py", line 88, in wrapped\n    raise CommandInvokeError(exc) from exc\ndiscord.ext.commands.errors.CommandInvokeError: Command raised an exception: AttributeError: 'Role' object has no attribute 'casefold'\n\n```
Message logged at 01/25/20 14:09:26 by Bot David8#4665 in Channel Direct Message with Vyryn#4618: with Content: ```py\nTraceback (most recent call last):\n  File "C:\Python37\lib\site-packages\discord\ext\commands\core.py", line 79, in wrapped\n    ret = await coro(*args, **kwargs)\n  File "C:\Users\Vyryn\PycharmProjects\davidbot\cogs\corp.py", line 391, in reqdiv\n    for div in divs_list:\nOSError: [Errno 22] Invalid argument\n\nThe above exception was the direct cause of the following exception:\n\nTraceback (most recent call last):\n  File "C:\Python37\lib\site-packages\discord\ext\commands\bot.py", line 863, in invoke\n    await ctx.command.invoke(ctx)\n  File "C:\Python37\lib\site-packages\discord\ext\commands\core.py", line 728, in invoke\n    await injected(*ctx.args, **ctx.kwargs)\n  File "C:\Python37\lib\site-packages\discord\ext\commands\core.py", line 88, in wrapped\n    raise CommandInvokeError(exc) from exc\ndiscord.ext.commands.errors.CommandInvokeError: Command raised an exception: OSError: [Errno 22] Invalid argument\n\n```
Message logged at 01/25/20 14:09:26 by Bot David8#4665 in Channel Direct Message with Vyryn#4618: with Content: ```py\nTraceback (most recent call last):\n  File "C:\Python37\lib\site-packages\discord\ext\commands\core.py", line 79, in wrapped\n    ret = await coro(*args, **kwargs)\n  File "C:\Users\Vyryn\PycharmProjects\davidbot\cogs\corp.py", line 391, in reqdiv\n    for div in divs_list:\nOSError: [Errno 22] Invalid argument\n\nThe above exception was the direct cause of the following exception:\n\nTraceback (most recent call last):\n  File "C:\Python37\lib\site-packages\discord\ext\commands\bot.py", line 863, in invoke\n    await ctx.command.invoke(ctx)\n  File "C:\Python37\lib\site-packages\discord\ext\commands\core.py", line 728, in invoke\n    await injected(*ctx.args, **ctx.kwargs)\n  File "C:\Python37\lib\site-packages\discord\ext\commands\core.py", line 88, in wrapped\n    raise CommandInvokeError(exc) from exc\ndiscord.ext.commands.errors.CommandInvokeError: Command raised an exception: OSError: [Errno 22] Invalid argument\n\n```
Message logged at 01/25/20 14:09:49 by Bot David8#4665 in Channel Direct Message with Vyryn#4618: with Content: ```py\nTraceback (most recent call last):\n  File "C:\Python37\lib\site-packages\discord\ext\commands\core.py", line 79, in wrapped\n    ret = await coro(*args, **kwargs)\n  File "C:\Users\Vyryn\PycharmProjects\davidbot\cogs\corp.py", line 391, in reqdiv\n    for div in divs_list:\nOSError: [Errno 22] Invalid argument\n\nThe above exception was the direct cause of the following exception:\n\nTraceback (most recent call last):\n  File "C:\Python37\lib\site-packages\discord\ext\commands\bot.py", line 863, in invoke\n    await ctx.command.invoke(ctx)\n  File "C:\Python37\lib\site-packages\discord\ext\commands\core.py", line 728, in invoke\n    await injected(*ctx.args, **ctx.kwargs)\n  File "C:\Python37\lib\site-packages\discord\ext\commands\core.py", line 88, in wrapped\n    raise CommandInvokeError(exc) from exc\ndiscord.ext.commands.errors.CommandInvokeError: Command raised an exception: OSError: [Errno 22] Invalid argument\n\n```
Message logged at 01/25/20 14:18:24 by Bot David8#4665 in Channel Direct Message with Vyryn#4618: with Content: ```py\nTraceback (most recent call last):\n  File "C:\Python37\lib\site-packages\discord\ext\commands\core.py", line 79, in wrapped\n    ret = await coro(*args, **kwargs)\n  File "C:\Users\Vyryn\PycharmProjects\davidbot\cogs\corp.py", line 391, in reqdiv\n    print(divs_list)\nOSError: [Errno 22] Invalid argument\n\nThe above exception was the direct cause of the following exception:\n\nTraceback (most recent call last):\n  File "C:\Python37\lib\site-packages\discord\ext\commands\bot.py", line 863, in invoke\n    await ctx.command.invoke(ctx)\n  File "C:\Python37\lib\site-packages\discord\ext\commands\core.py", line 728, in invoke\n    await injected(*ctx.args, **ctx.kwargs)\n  File "C:\Python37\lib\site-packages\discord\ext\commands\core.py", line 88, in wrapped\n    raise CommandInvokeError(exc) from exc\ndiscord.ext.commands.errors.CommandInvokeError: Command raised an exception: OSError: [Errno 22] Invalid argument\n\n```
Message logged at 01/25/20 14:18:24 by Bot David8#4665 in Channel Direct Message with Vyryn#4618: with Content: ```py\nTraceback (most recent call last):\n  File "C:\Python37\lib\site-packages\discord\ext\commands\core.py", line 79, in wrapped\n    ret = await coro(*args, **kwargs)\n  File "C:\Users\Vyryn\PycharmProjects\davidbot\cogs\corp.py", line 391, in reqdiv\n    print(divs_list)\nOSError: [Errno 22] Invalid argument\n\nThe above exception was the direct cause of the following exception:\n\nTraceback (most recent call last):\n  File "C:\Python37\lib\site-packages\discord\ext\commands\bot.py", line 863, in invoke\n    await ctx.command.invoke(ctx)\n  File "C:\Python37\lib\site-packages\discord\ext\commands\core.py", line 728, in invoke\n    await injected(*ctx.args, **ctx.kwargs)\n  File "C:\Python37\lib\site-packages\discord\ext\commands\core.py", line 88, in wrapped\n    raise CommandInvokeError(exc) from exc\ndiscord.ext.commands.errors.CommandInvokeError: Command raised an exception: OSError: [Errno 22] Invalid argument\n\n```
Message logged at 01/25/20 14:38:08 by Bot David8#4665 in Channel Direct Message with Vyryn#4618: with Content: ```py\nTraceback (most recent call last):\n  File "C:\Python37\lib\site-packages\discord\ext\commands\core.py", line 79, in wrapped\n    ret = await coro(*args, **kwargs)\n  File "C:\Users\Vyryn\PycharmProjects\davidbot\cogs\dev.py", line 153, in reload\n    self.bot.unload_extension(f'cogs.{extension}')\n  File "C:\Python37\lib\site-packages\discord\ext\commands\bot.py", line 655, in unload_extension\n    self._remove_module_references(lib.__name__)\n  File "C:\Python37\lib\site-packages\discord\ext\commands\bot.py", line 534, in _remove_module_references\n    self.remove_cog(cogname)\n  File "C:\Python37\lib\site-packages\discord\ext\commands\bot.py", line 520, in remove_cog\n    cog._eject(self)\n  File "C:\Python37\lib\site-packages\discord\ext\commands\cog.py", line 414, in _eject\n    self.cog_unload()\n  File "C:\Users\Vyryn\PycharmProjects\davidbot\cogs\corp.py", line 134, in cog_unload\n    self.session.close()\nAttributeError: 'Corp' object has no attribute 'session'\n\nThe above exception was the direct cause of the following exception:\n\nTraceback (most recent call last):\n  File "C:\Python37\lib\site-packages\discord\ext\commands\bot.py", line 863, in invoke\n    await ctx.command.invoke(ctx)\n  File "C:\Python37\lib\site-packages\discord\ext\commands\core.py", line 728, in invoke\n    await injected(*ctx.args, **ctx.kwargs)\n  File "C:\Python37\lib\site-packages\discord\ext\commands\core.py", line 88, in wrapped\n    raise CommandInvokeError(exc) from exc\ndiscord.ext.commands.errors.CommandInvokeError: Command raised an exception: AttributeError: 'Corp' object has no attribute 'session'\n\n```
Message logged at 01/25/20 14:40:19 by Bot David8#4665 in Channel Direct Message with Vyryn#4618: with Content: Error in command reload: Command raised an exception: AttributeError: 'Corp' object has no attribute 'session'.
Message logged at 01/25/20 14:40:20 by Bot David8#4665 in Channel Direct Message with Vyryn#4618: with Content: ```py\nTraceback (most recent call last):\n  File "C:\Python37\lib\site-packages\discord\ext\commands\core.py", line 79, in wrapped\n    ret = await coro(*args, **kwargs)\n  File "C:\Users\Vyryn\PycharmProjects\davidbot\cogs\dev.py", line 153, in reload\n    self.bot.unload_extension(f'cogs.{extension}')\n  File "C:\Python37\lib\site-packages\discord\ext\commands\bot.py", line 655, in unload_extension\n    self._remove_module_references(lib.__name__)\n  File "C:\Python37\lib\site-packages\discord\ext\commands\bot.py", line 534, in _remove_module_references\n    self.remove_cog(cogname)\n  File "C:\Python37\lib\site-packages\discord\ext\commands\bot.py", line 520, in remove_cog\n    cog._eject(self)\n  File "C:\Python37\lib\site-packages\discord\ext\commands\cog.py", line 414, in _eject\n    self.cog_unload()\n  File "C:\Users\Vyryn\PycharmProjects\davidbot\cogs\corp.py", line 134, in cog_unload\n    self.session.close()\nAttributeError: 'Corp' object has no attribute 'session'\n\nThe above exception was the direct cause of the following exception:\n\nTraceback (most recent call last):\n  File "C:\Python37\lib\site-packages\discord\ext\commands\bot.py", line 863, in invoke\n    await ctx.command.invoke(ctx)\n  File "C:\Python37\lib\site-packages\discord\ext\commands\core.py", line 728, in invoke\n    await injected(*ctx.args, **ctx.kwargs)\n  File "C:\Python37\lib\site-packages\discord\ext\commands\core.py", line 88, in wrapped\n    raise CommandInvokeError(exc) from exc\ndiscord.ext.commands.errors.CommandInvokeError: Command raised an exception: AttributeError: 'Corp' object has no attribute 'session'\n\n```
Message logged at 01/25/20 14:41:08 by Bot David8#4665 in Channel Direct Message with Vyryn#4618: with Content: Hey Vyryn, there was an error in the command reload: Command raised an exception: AttributeError: 'Corp' object has no attribute 'session'.\n It was used by Vyryn#4618 in sample corp server, registration.
Message logged at 01/25/20 14:41:08 by Bot David8#4665 in Channel Direct Message with Vyryn#4618: with Content: ```py\nTraceback (most recent call last):\n  File "C:\Python37\lib\site-packages\discord\ext\commands\core.py", line 79, in wrapped\n    ret = await coro(*args, **kwargs)\n  File "C:\Users\Vyryn\PycharmProjects\davidbot\cogs\dev.py", line 153, in reload\n    self.bot.unload_extension(f'cogs.{extension}')\n  File "C:\Python37\lib\site-packages\discord\ext\commands\bot.py", line 655, in unload_extension\n    self._remove_module_references(lib.__name__)\n  File "C:\Python37\lib\site-packages\discord\ext\commands\bot.py", line 534, in _remove_module_references\n    self.remove_cog(cogname)\n  File "C:\Python37\lib\site-packages\discord\ext\commands\bot.py", line 520, in remove_cog\n    cog._eject(self)\n  File "C:\Python37\lib\site-packages\discord\ext\commands\cog.py", line 414, in _eject\n    self.cog_unload()\n  File "C:\Users\Vyryn\PycharmProjects\davidbot\cogs\corp.py", line 134, in cog_unload\n    self.session.close()\nAttributeError: 'Corp' object has no attribute 'session'\n\nThe above exception was the direct cause of the following exception:\n\nTraceback (most recent call last):\n  File "C:\Python37\lib\site-packages\discord\ext\commands\bot.py", line 863, in invoke\n    await ctx.command.invoke(ctx)\n  File "C:\Python37\lib\site-packages\discord\ext\commands\core.py", line 728, in invoke\n    await injected(*ctx.args, **ctx.kwargs)\n  File "C:\Python37\lib\site-packages\discord\ext\commands\core.py", line 88, in wrapped\n    raise CommandInvokeError(exc) from exc\ndiscord.ext.commands.errors.CommandInvokeError: Command raised an exception: AttributeError: 'Corp' object has no attribute 'session'\n\n```
Message logged at 01/25/20 16:58:00 by Bot David8#4665 in Channel Direct Message with Vyryn#4618: with Content: Hey Vyryn, there was an error in the command eval: Command raised an exception: NameError: name 'py' is not defined.\n It was used by Vyryn#4618 in V's Private Server, cafe-bot-2.
Message logged at 01/25/20 16:58:00 by Bot David8#4665 in Channel Direct Message with Vyryn#4618: with Content: ```py\nTraceback (most recent call last):\n  File "C:\Python37\lib\site-packages\discord\ext\commands\core.py", line 79, in wrapped\n    ret = await coro(*args, **kwargs)\n  File "C:\Users\Vyryn\PycharmProjects\davidbot\cogs\dev.py", line 221, in eval_fn\n    'ctx': ctx,\n  File "<ast>", line 2, in _eval_expr\nNameError: name 'py' is not defined\n\nThe above exception was the direct cause of the following exception:\n\nTraceback (most recent call last):\n  File "C:\Python37\lib\site-packages\discord\ext\commands\bot.py", line 863, in invoke\n    await ctx.command.invoke(ctx)\n  File "C:\Python37\lib\site-packages\discord\ext\commands\core.py", line 728, in invoke\n    await injected(*ctx.args, **ctx.kwargs)\n  File "C:\Python37\lib\site-packages\discord\ext\commands\core.py", line 88, in wrapped\n    raise CommandInvokeError(exc) from exc\ndiscord.ext.commands.errors.CommandInvokeError: Command raised an exception: NameError: name 'py' is not defined\n\n```
Message logged at 01/25/20 19:05:31 by Bot David8#4665 in Channel Direct Message with Vyryn#4618: with Content: Hey Vyryn, there was an error in the command reload: Command raised an exception: IndentationError: unexpected indent (database.py, line 43).\n It was used by Vyryn#4618 in V's Private Server, david-bot-testing.
Message logged at 01/25/20 19:05:31 by Bot David8#4665 in Channel Direct Message with Vyryn#4618: with Content: ```py\nTraceback (most recent call last):\n  File "C:\Python37\lib\site-packages\discord\ext\commands\core.py", line 79, in wrapped\n    ret = await coro(*args, **kwargs)\n  File "C:\Users\Vyryn\PycharmProjects\davidbot\cogs\dev.py", line 157, in reload\n    self.bot.load_extension(f'cogs.{extension}')\n  File "C:\Python37\lib\site-packages\discord\ext\commands\bot.py", line 621, in load_extension\n    lib = importlib.import_module(name)\n  File "C:\Python37\lib\importlib\__init__.py", line 127, in import_module\n    return _bootstrap._gcd_import(name[level:], package, level)\n  File "<frozen importlib._bootstrap>", line 1006, in _gcd_import\n  File "<frozen importlib._bootstrap>", line 983, in _find_and_load\n  File "<frozen importlib._bootstrap>", line 967, in _find_and_load_unlocked\n  File "<frozen importlib._bootstrap>", line 677, in _load_unlocked\n  File "<frozen importlib._bootstrap_external>", line 724, in exec_module\n  File "<frozen importlib._bootstrap_external>", line 860, in get_code\n  File "<frozen importlib._bootstrap_external>", line 791, in source_to_code\n  File "<frozen importlib._bootstrap>", line 219, in _call_with_frames_removed\n  File "C:\Users\Vyryn\PycharmProjects\davidbot\cogs\database.py", line 43\n    print('Users table not found. Creating a new one...')\n    ^\nIndentationError: unexpected indent\n\nThe above exception was the direct cause of the following exception:\n\nTraceback (most recent call last):\n  File "C:\Python37\lib\site-packages\discord\ext\commands\bot.py", line 863, in invoke\n    await ctx.command.invoke(ctx)\n  File "C:\Python37\lib\site-packages\discord\ext\commands\core.py", line 728, in invoke\n    await injected(*ctx.args, **ctx.kwargs)\n  File "C:\Python37\lib\site-packages\discord\ext\commands\core.py", line 88, in wrapped\n    raise CommandInvokeError(exc) from exc\ndiscord.ext.commands.errors.CommandInvokeError: Command raised an exception: IndentationError: unexpected indent (database.py, line 43)\n\n```
Message logged at 01/25/20 19:05:34 by Bot David8#4665 in Channel Direct Message with Vyryn#4618: with Content: Hey Vyryn, there was an error in the command load: Command raised an exception: IndentationError: unexpected indent (database.py, line 43).\n It was used by Vyryn#4618 in V's Private Server, david-bot-testing.
Message logged at 01/25/20 19:05:34 by Bot David8#4665 in Channel Direct Message with Vyryn#4618: with Content: ```py\nTraceback (most recent call last):\n  File "C:\Python37\lib\site-packages\discord\ext\commands\core.py", line 79, in wrapped\n    ret = await coro(*args, **kwargs)\n  File "C:/Users/Vyryn/PycharmProjects/davidbot/bot.py", line 119, in load\n    bot.load_extension(f'cogs.{extension}')\n  File "C:\Python37\lib\site-packages\discord\ext\commands\bot.py", line 621, in load_extension\n    lib = importlib.import_module(name)\n  File "C:\Python37\lib\importlib\__init__.py", line 127, in import_module\n    return _bootstrap._gcd_import(name[level:], package, level)\n  File "<frozen importlib._bootstrap>", line 1006, in _gcd_import\n  File "<frozen importlib._bootstrap>", line 983, in _find_and_load\n  File "<frozen importlib._bootstrap>", line 967, in _find_and_load_unlocked\n  File "<frozen importlib._bootstrap>", line 677, in _load_unlocked\n  File "<frozen importlib._bootstrap_external>", line 724, in exec_module\n  File "<frozen importlib._bootstrap_external>", line 860, in get_code\n  File "<frozen importlib._bootstrap_external>", line 791, in source_to_code\n  File "<frozen importlib._bootstrap>", line 219, in _call_with_frames_removed\n  File "C:\Users\Vyryn\PycharmProjects\davidbot\cogs\database.py", line 43\n    print('Users table not found. Creating a new one...')\n    ^\nIndentationError: unexpected indent\n\nThe above exception was the direct cause of the following exception:\n\nTraceback (most recent call last):\n  File "C:\Python37\lib\site-packages\discord\ext\commands\bot.py", line 863, in invoke\n    await ctx.command.invoke(ctx)\n  File "C:\Python37\lib\site-packages\discord\ext\commands\core.py", line 728, in invoke\n    await injected(*ctx.args, **ctx.kwargs)\n  File "C:\Python37\lib\site-packages\discord\ext\commands\core.py", line 88, in wrapped\n    raise CommandInvokeError(exc) from exc\ndiscord.ext.commands.errors.CommandInvokeError: Command raised an exception: IndentationError: unexpected indent (database.py, line 43)\n\n```
Message logged at 01/25/20 19:09:32 by Bot David8#4665 in Channel Direct Message with Vyryn#4618: with Content: Hey Vyryn, there was an error in the command adduser: Command raised an exception: ProgrammingError: Not all parameters were used in the SQL statement.\n It was used by Vyryn#4618 in V's Private Server, david-bot-testing.
Message logged at 01/25/20 19:09:32 by Bot David8#4665 in Channel Direct Message with Vyryn#4618: with Content: ```py\nTraceback (most recent call last):\n  File "C:\Python37\lib\site-packages\discord\ext\commands\core.py", line 79, in wrapped\n    ret = await coro(*args, **kwargs)\n  File "C:\Users\Vyryn\PycharmProjects\davidbot\cogs\database.py", line 67, in adduser\n    result = adduser(user)\n  File "C:\Users\Vyryn\PycharmProjects\davidbot\cogs\database.py", line 26, in adduser\n    cursor.execute(query, values)\n  File "C:\Users\Vyryn\PycharmProjects\vbot\venv\lib\site-packages\mysql\connector\cursor.py", line 543, in execute\n    "Not all parameters were used in the SQL statement")\nmysql.connector.errors.ProgrammingError: Not all parameters were used in the SQL statement\n\nThe above exception was the direct cause of the following exception:\n\nTraceback (most recent call last):\n  File "C:\Python37\lib\site-packages\discord\ext\commands\bot.py", line 863, in invoke\n    await ctx.command.invoke(ctx)\n  File "C:\Python37\lib\site-packages\discord\ext\commands\core.py", line 728, in invoke\n    await injected(*ctx.args, **ctx.kwargs)\n  File "C:\Python37\lib\site-packages\discord\ext\commands\core.py", line 88, in wrapped\n    raise CommandInvokeError(exc) from exc\ndiscord.ext.commands.errors.CommandInvokeError: Command raised an exception: ProgrammingError: Not all parameters were used in the SQL statement\n\n```
Message logged at 01/25/20 19:10:09 by Bot David8#4665 in Channel Direct Message with Vyryn#4618: with Content: Hey Vyryn, there was an error in the command adduser: Command raised an exception: ProgrammingError: Not all parameters were used in the SQL statement.\n It was used by Vyryn#4618 in V's Private Server, david-bot-testing.
Message logged at 01/25/20 19:10:09 by Bot David8#4665 in Channel Direct Message with Vyryn#4618: with Content: ```py\nTraceback (most recent call last):\n  File "C:\Python37\lib\site-packages\discord\ext\commands\core.py", line 79, in wrapped\n    ret = await coro(*args, **kwargs)\n  File "C:\Users\Vyryn\PycharmProjects\davidbot\cogs\database.py", line 67, in adduser\n    result = adduser(user)\n  File "C:\Users\Vyryn\PycharmProjects\davidbot\cogs\database.py", line 26, in adduser\n    cursor.execute(query, values)\n  File "C:\Users\Vyryn\PycharmProjects\vbot\venv\lib\site-packages\mysql\connector\cursor.py", line 543, in execute\n    "Not all parameters were used in the SQL statement")\nmysql.connector.errors.ProgrammingError: Not all parameters were used in the SQL statement\n\nThe above exception was the direct cause of the following exception:\n\nTraceback (most recent call last):\n  File "C:\Python37\lib\site-packages\discord\ext\commands\bot.py", line 863, in invoke\n    await ctx.command.invoke(ctx)\n  File "C:\Python37\lib\site-packages\discord\ext\commands\core.py", line 728, in invoke\n    await injected(*ctx.args, **ctx.kwargs)\n  File "C:\Python37\lib\site-packages\discord\ext\commands\core.py", line 88, in wrapped\n    raise CommandInvokeError(exc) from exc\ndiscord.ext.commands.errors.CommandInvokeError: Command raised an exception: ProgrammingError: Not all parameters were used in the SQL statement\n\n```
Message logged at 01/25/20 19:11:14 by Bot David8#4665 in Channel Direct Message with Vyryn#4618: with Content: Hey Vyryn, there was an error in the command adduser: Command raised an exception: ProgrammingError: Not all parameters were used in the SQL statement.\n It was used by Vyryn#4618 in V's Private Server, david-bot-testing.
Message logged at 01/25/20 19:11:14 by Bot David8#4665 in Channel Direct Message with Vyryn#4618: with Content: ```py\nTraceback (most recent call last):\n  File "C:\Python37\lib\site-packages\discord\ext\commands\core.py", line 79, in wrapped\n    ret = await coro(*args, **kwargs)\n  File "C:\Users\Vyryn\PycharmProjects\davidbot\cogs\database.py", line 67, in adduser\n    result = adduser(user)\n  File "C:\Users\Vyryn\PycharmProjects\davidbot\cogs\database.py", line 26, in adduser\n    cursor.execute(query, values)\n  File "C:\Users\Vyryn\PycharmProjects\vbot\venv\lib\site-packages\mysql\connector\cursor.py", line 543, in execute\n    "Not all parameters were used in the SQL statement")\nmysql.connector.errors.ProgrammingError: Not all parameters were used in the SQL statement\n\nThe above exception was the direct cause of the following exception:\n\nTraceback (most recent call last):\n  File "C:\Python37\lib\site-packages\discord\ext\commands\bot.py", line 863, in invoke\n    await ctx.command.invoke(ctx)\n  File "C:\Python37\lib\site-packages\discord\ext\commands\core.py", line 728, in invoke\n    await injected(*ctx.args, **ctx.kwargs)\n  File "C:\Python37\lib\site-packages\discord\ext\commands\core.py", line 88, in wrapped\n    raise CommandInvokeError(exc) from exc\ndiscord.ext.commands.errors.CommandInvokeError: Command raised an exception: ProgrammingError: Not all parameters were used in the SQL statement\n\n```
Message logged at 01/25/20 19:12:07 by Bot David8#4665 in Channel Direct Message with Vyryn#4618: with Content: Hey Vyryn, there was an error in the command adduser: Command raised an exception: DataError: 1264 (22003): Out of range value for column 'id' at row 1.\n It was used by Vyryn#4618 in V's Private Server, david-bot-testing.
Message logged at 01/25/20 19:12:07 by Bot David8#4665 in Channel Direct Message with Vyryn#4618: with Content: ```py\nTraceback (most recent call last):\n  File "C:\Python37\lib\site-packages\discord\ext\commands\core.py", line 79, in wrapped\n    ret = await coro(*args, **kwargs)\n  File "C:\Users\Vyryn\PycharmProjects\davidbot\cogs\database.py", line 67, in adduser\n    result = adduser(user)\n  File "C:\Users\Vyryn\PycharmProjects\davidbot\cogs\database.py", line 26, in adduser\n    cursor.execute(query, values)\n  File "C:\Users\Vyryn\PycharmProjects\vbot\venv\lib\site-packages\mysql\connector\cursor.py", line 551, in execute\n    self._handle_result(self._connection.cmd_query(stmt))\n  File "C:\Users\Vyryn\PycharmProjects\vbot\venv\lib\site-packages\mysql\connector\connection.py", line 490, in cmd_query\n    result = self._handle_result(self._send_cmd(ServerCmd.QUERY, query))\n  File "C:\Users\Vyryn\PycharmProjects\vbot\venv\lib\site-packages\mysql\connector\connection.py", line 395, in _handle_result\n    raise errors.get_exception(packet)\nmysql.connector.errors.DataError: 1264 (22003): Out of range value for column 'id' at row 1\n\nThe above exception was the direct cause of the following exception:\n\nTraceback (most recent call last):\n  File "C:\Python37\lib\site-packages\discord\ext\commands\bot.py", line 863, in invoke\n    await ctx.command.invoke(ctx)\n  File "C:\Python37\lib\site-packages\discord\ext\commands\core.py", line 728, in invoke\n    await injected(*ctx.args, **ctx.kwargs)\n  File "C:\Python37\lib\site-packages\discord\ext\commands\core.py", line 88, in wrapped\n    raise CommandInvokeError(exc) from exc\ndiscord.ext.commands.errors.CommandInvokeError: Command raised an exception: DataError: 1264 (22003): Out of range value for column 'id' at row 1\n\n```
Message logged at 01/25/20 19:20:26 by Bot David8#4665 in Channel Direct Message with Vyryn#4618: with Content: Hey Vyryn, there was an error in the command adduser: Command raised an exception: DataError: 1264 (22003): Out of range value for column 'id' at row 1.\n It was used by Vyryn#4618 in V's Private Server, david-bot-testing.
Message logged at 01/25/20 19:20:26 by Bot David8#4665 in Channel Direct Message with Vyryn#4618: with Content: ```py\nTraceback (most recent call last):\n  File "C:\Python37\lib\site-packages\discord\ext\commands\core.py", line 79, in wrapped\n    ret = await coro(*args, **kwargs)\n  File "C:\Users\Vyryn\PycharmProjects\davidbot\cogs\database.py", line 67, in adduser\n    result = adduser(user)\n  File "C:\Users\Vyryn\PycharmProjects\davidbot\cogs\database.py", line 26, in adduser\n    cursor.execute(query, values)\n  File "C:\Users\Vyryn\PycharmProjects\vbot\venv\lib\site-packages\mysql\connector\cursor.py", line 551, in execute\n    self._handle_result(self._connection.cmd_query(stmt))\n  File "C:\Users\Vyryn\PycharmProjects\vbot\venv\lib\site-packages\mysql\connector\connection.py", line 490, in cmd_query\n    result = self._handle_result(self._send_cmd(ServerCmd.QUERY, query))\n  File "C:\Users\Vyryn\PycharmProjects\vbot\venv\lib\site-packages\mysql\connector\connection.py", line 395, in _handle_result\n    raise errors.get_exception(packet)\nmysql.connector.errors.DataError: 1264 (22003): Out of range value for column 'id' at row 1\n\nThe above exception was the direct cause of the following exception:\n\nTraceback (most recent call last):\n  File "C:\Python37\lib\site-packages\discord\ext\commands\bot.py", line 863, in invoke\n    await ctx.command.invoke(ctx)\n  File "C:\Python37\lib\site-packages\discord\ext\commands\core.py", line 728, in invoke\n    await injected(*ctx.args, **ctx.kwargs)\n  File "C:\Python37\lib\site-packages\discord\ext\commands\core.py", line 88, in wrapped\n    raise CommandInvokeError(exc) from exc\ndiscord.ext.commands.errors.CommandInvokeError: Command raised an exception: DataError: 1264 (22003): Out of range value for column 'id' at row 1\n\n```
Message logged at 01/25/20 19:21:02 by Bot David8#4665 in Channel Direct Message with Vyryn#4618: with Content: Hey Vyryn, there was an error in the command adduser: Command raised an exception: DataError: 1264 (22003): Out of range value for column 'id' at row 1.\n It was used by Vyryn#4618 in V's Private Server, david-bot-testing.
Message logged at 01/25/20 19:21:03 by Bot David8#4665 in Channel Direct Message with Vyryn#4618: with Content: ```py\nTraceback (most recent call last):\n  File "C:\Python37\lib\site-packages\discord\ext\commands\core.py", line 79, in wrapped\n    ret = await coro(*args, **kwargs)\n  File "C:\Users\Vyryn\PycharmProjects\davidbot\cogs\database.py", line 67, in adduser\n    result = adduser(user)\n  File "C:\Users\Vyryn\PycharmProjects\davidbot\cogs\database.py", line 26, in adduser\n    cursor.execute(query, values)\n  File "C:\Users\Vyryn\PycharmProjects\vbot\venv\lib\site-packages\mysql\connector\cursor.py", line 551, in execute\n    self._handle_result(self._connection.cmd_query(stmt))\n  File "C:\Users\Vyryn\PycharmProjects\vbot\venv\lib\site-packages\mysql\connector\connection.py", line 490, in cmd_query\n    result = self._handle_result(self._send_cmd(ServerCmd.QUERY, query))\n  File "C:\Users\Vyryn\PycharmProjects\vbot\venv\lib\site-packages\mysql\connector\connection.py", line 395, in _handle_result\n    raise errors.get_exception(packet)\nmysql.connector.errors.DataError: 1264 (22003): Out of range value for column 'id' at row 1\n\nThe above exception was the direct cause of the following exception:\n\nTraceback (most recent call last):\n  File "C:\Python37\lib\site-packages\discord\ext\commands\bot.py", line 863, in invoke\n    await ctx.command.invoke(ctx)\n  File "C:\Python37\lib\site-packages\discord\ext\commands\core.py", line 728, in invoke\n    await injected(*ctx.args, **ctx.kwargs)\n  File "C:\Python37\lib\site-packages\discord\ext\commands\core.py", line 88, in wrapped\n    raise CommandInvokeError(exc) from exc\ndiscord.ext.commands.errors.CommandInvokeError: Command raised an exception: DataError: 1264 (22003): Out of range value for column 'id' at row 1\n\n```
Message logged at 01/25/20 19:22:00 by Bot David8#4665 in Channel Direct Message with Vyryn#4618: with Content: Hey Vyryn, there was an error in the command adduser: Command raised an exception: TypeError: 'int' object is not subscriptable.\n It was used by Vyryn#4618 in V's Private Server, david-bot-testing.
Message logged at 01/25/20 19:22:01 by Bot David8#4665 in Channel Direct Message with Vyryn#4618: with Content: ```py\nTraceback (most recent call last):\n  File "C:\Python37\lib\site-packages\discord\ext\commands\core.py", line 79, in wrapped\n    ret = await coro(*args, **kwargs)\n  File "C:\Users\Vyryn\PycharmProjects\davidbot\cogs\database.py", line 67, in adduser\n    result = adduser(user)\n  File "C:\Users\Vyryn\PycharmProjects\davidbot\cogs\database.py", line 25, in adduser\n    values = (user.id[0:3], user.name, str(user))\nTypeError: 'int' object is not subscriptable\n\nThe above exception was the direct cause of the following exception:\n\nTraceback (most recent call last):\n  File "C:\Python37\lib\site-packages\discord\ext\commands\bot.py", line 863, in invoke\n    await ctx.command.invoke(ctx)\n  File "C:\Python37\lib\site-packages\discord\ext\commands\core.py", line 728, in invoke\n    await injected(*ctx.args, **ctx.kwargs)\n  File "C:\Python37\lib\site-packages\discord\ext\commands\core.py", line 88, in wrapped\n    raise CommandInvokeError(exc) from exc\ndiscord.ext.commands.errors.CommandInvokeError: Command raised an exception: TypeError: 'int' object is not subscriptable\n\n```
Message logged at 01/25/20 19:33:42 by Bot David8#4665 in Channel Direct Message with Vyryn#4618: with Content: Hey Vyryn, there was an error in the command adduser: Command raised an exception: IntegrityError: 1062 (23000): Duplicate entry '663278592' for key 'PRIMARY'.\n It was used by Vyryn#4618 in V's Private Server, david-bot-testing.
Message logged at 01/25/20 19:33:42 by Bot David8#4665 in Channel Direct Message with Vyryn#4618: with Content: ```py\nTraceback (most recent call last):\n  File "C:\Python37\lib\site-packages\discord\ext\commands\core.py", line 79, in wrapped\n    ret = await coro(*args, **kwargs)\n  File "C:\Users\Vyryn\PycharmProjects\davidbot\cogs\database.py", line 67, in adduser\n    result = adduser(user)\n  File "C:\Users\Vyryn\PycharmProjects\davidbot\cogs\database.py", line 26, in adduser\n    cursor.execute(query, values)\n  File "C:\Users\Vyryn\PycharmProjects\vbot\venv\lib\site-packages\mysql\connector\cursor.py", line 551, in execute\n    self._handle_result(self._connection.cmd_query(stmt))\n  File "C:\Users\Vyryn\PycharmProjects\vbot\venv\lib\site-packages\mysql\connector\connection.py", line 490, in cmd_query\n    result = self._handle_result(self._send_cmd(ServerCmd.QUERY, query))\n  File "C:\Users\Vyryn\PycharmProjects\vbot\venv\lib\site-packages\mysql\connector\connection.py", line 395, in _handle_result\n    raise errors.get_exception(packet)\nmysql.connector.errors.IntegrityError: 1062 (23000): Duplicate entry '663278592' for key 'PRIMARY'\n\nThe above exception was the direct cause of the following exception:\n\nTraceback (most recent call last):\n  File "C:\Python37\lib\site-packages\discord\ext\commands\bot.py", line 863, in invoke\n    await ctx.command.invoke(ctx)\n  File "C:\Python37\lib\site-packages\discord\ext\commands\core.py", line 728, in invoke\n    await injected(*ctx.args, **ctx.kwargs)\n  File "C:\Python37\lib\site-packages\discord\ext\commands\core.py", line 88, in wrapped\n    raise CommandInvokeError(exc) from exc\ndiscord.ext.commands.errors.CommandInvokeError: Command raised an exception: IntegrityError: 1062 (23000): Duplicate entry '663278592' for key 'PRIMARY'\n\n```
Message logged at 01/25/20 19:45:54 by Bot David8#4665 in Channel Direct Message with Vyryn#4618: with Content: Hey Vyryn, there was an error in the command adduser: Command raised an exception: DataError: 1264 (22003): Out of range value for column 'id' at row 1.\n It was used by Vyryn#4618 in V's Private Server, david-bot-testing.
Message logged at 01/25/20 19:45:54 by Bot David8#4665 in Channel Direct Message with Vyryn#4618: with Content: ```py\nTraceback (most recent call last):\n  File "C:\Python37\lib\site-packages\discord\ext\commands\core.py", line 79, in wrapped\n    ret = await coro(*args, **kwargs)\n  File "C:\Users\Vyryn\PycharmProjects\davidbot\cogs\database.py", line 71, in adduser\n    result = adduser(user)\n  File "C:\Users\Vyryn\PycharmProjects\davidbot\cogs\database.py", line 28, in adduser\n    cursor.execute(query, values)\n  File "C:\Users\Vyryn\PycharmProjects\vbot\venv\lib\site-packages\mysql\connector\cursor.py", line 551, in execute\n    self._handle_result(self._connection.cmd_query(stmt))\n  File "C:\Users\Vyryn\PycharmProjects\vbot\venv\lib\site-packages\mysql\connector\connection.py", line 490, in cmd_query\n    result = self._handle_result(self._send_cmd(ServerCmd.QUERY, query))\n  File "C:\Users\Vyryn\PycharmProjects\vbot\venv\lib\site-packages\mysql\connector\connection.py", line 395, in _handle_result\n    raise errors.get_exception(packet)\nmysql.connector.errors.DataError: 1264 (22003): Out of range value for column 'id' at row 1\n\nThe above exception was the direct cause of the following exception:\n\nTraceback (most recent call last):\n  File "C:\Python37\lib\site-packages\discord\ext\commands\bot.py", line 863, in invoke\n    await ctx.command.invoke(ctx)\n  File "C:\Python37\lib\site-packages\discord\ext\commands\core.py", line 728, in invoke\n    await injected(*ctx.args, **ctx.kwargs)\n  File "C:\Python37\lib\site-packages\discord\ext\commands\core.py", line 88, in wrapped\n    raise CommandInvokeError(exc) from exc\ndiscord.ext.commands.errors.CommandInvokeError: Command raised an exception: DataError: 1264 (22003): Out of range value for column 'id' at row 1\n\n```
Message logged at 01/25/20 20:31:11 by Bot David8#4665 in Channel Direct Message with Vyryn#4618: with Content: Hey Vyryn, there was an error in the command adduser: Command raised an exception: AttributeError: module 'random' has no attribute 'choose'.\n It was used by Vyryn#4618 in V's Private Server, david-bot-testing.
Message logged at 01/25/20 20:31:11 by Bot David8#4665 in Channel Direct Message with Vyryn#4618: with Content: ```py\nTraceback (most recent call last):\n  File "C:\Python37\lib\site-packages\discord\ext\commands\core.py", line 79, in wrapped\n    ret = await coro(*args, **kwargs)\n  File "C:\Users\Vyryn\PycharmProjects\davidbot\cogs\corp.py", line 449, in adduser\n    hr_rep = random.choose(hr_reps)\nAttributeError: module 'random' has no attribute 'choose'\n\nThe above exception was the direct cause of the following exception:\n\nTraceback (most recent call last):\n  File "C:\Python37\lib\site-packages\discord\ext\commands\bot.py", line 863, in invoke\n    await ctx.command.invoke(ctx)\n  File "C:\Python37\lib\site-packages\discord\ext\commands\core.py", line 728, in invoke\n    await injected(*ctx.args, **ctx.kwargs)\n  File "C:\Python37\lib\site-packages\discord\ext\commands\core.py", line 88, in wrapped\n    raise CommandInvokeError(exc) from exc\ndiscord.ext.commands.errors.CommandInvokeError: Command raised an exception: AttributeError: module 'random' has no attribute 'choose'\n\n```
Message logged at 01/25/20 20:42:27 by Bot David8#4665 in Channel Direct Message with Vyryn#4618: with Content: Hey Vyryn, there was an error in the command directq: Command raised an exception: InterfaceError: No result set to fetch from..\n It was used by Vyryn#4618 in V's Private Server, david-bot-testing.
Message logged at 01/25/20 20:42:27 by Bot David8#4665 in Channel Direct Message with Vyryn#4618: with Content: ```py\nTraceback (most recent call last):\n  File "C:\Python37\lib\site-packages\discord\ext\commands\core.py", line 79, in wrapped\n    ret = await coro(*args, **kwargs)\n  File "C:\Users\Vyryn\PycharmProjects\davidbot\cogs\database.py", line 95, in directq\n    result = pquery(query)\n  File "C:\Users\Vyryn\PycharmProjects\davidbot\cogs\database.py", line 23, in pquery\n    return cursor.fetchall()\n  File "C:\Users\Vyryn\PycharmProjects\vbot\venv\lib\site-packages\mysql\connector\cursor.py", line 881, in fetchall\n    raise errors.InterfaceError("No result set to fetch from.")\nmysql.connector.errors.InterfaceError: No result set to fetch from.\n\nThe above exception was the direct cause of the following exception:\n\nTraceback (most recent call last):\n  File "C:\Python37\lib\site-packages\discord\ext\commands\bot.py", line 863, in invoke\n    await ctx.command.invoke(ctx)\n  File "C:\Python37\lib\site-packages\discord\ext\commands\core.py", line 728, in invoke\n    await injected(*ctx.args, **ctx.kwargs)\n  File "C:\Python37\lib\site-packages\discord\ext\commands\core.py", line 88, in wrapped\n    raise CommandInvokeError(exc) from exc\ndiscord.ext.commands.errors.CommandInvokeError: Command raised an exception: InterfaceError: No result set to fetch from.\n\n```
Message logged at 01/25/20 20:44:52 by Bot David8#4665 in Channel Direct Message with Vyryn#4618: with Content: Hey Vyryn, there was an error in the command directq: Command raised an exception: ProgrammingError: 1146 (42S02): Table 'datacamp.users' doesn't exist.\n It was used by Vyryn#4618 in V's Private Server, david-bot-testing.
Message logged at 01/25/20 20:44:52 by Bot David8#4665 in Channel Direct Message with Vyryn#4618: with Content: ```py\nTraceback (most recent call last):\n  File "C:\Python37\lib\site-packages\discord\ext\commands\core.py", line 79, in wrapped\n    ret = await coro(*args, **kwargs)\n  File "C:\Users\Vyryn\PycharmProjects\davidbot\cogs\database.py", line 95, in directq\n    result = pquery(query)\n  File "C:\Users\Vyryn\PycharmProjects\davidbot\cogs\database.py", line 22, in pquery\n    cursor.execute(querry)\n  File "C:\Users\Vyryn\PycharmProjects\vbot\venv\lib\site-packages\mysql\connector\cursor.py", line 551, in execute\n    self._handle_result(self._connection.cmd_query(stmt))\n  File "C:\Users\Vyryn\PycharmProjects\vbot\venv\lib\site-packages\mysql\connector\connection.py", line 490, in cmd_query\n    result = self._handle_result(self._send_cmd(ServerCmd.QUERY, query))\n  File "C:\Users\Vyryn\PycharmProjects\vbot\venv\lib\site-packages\mysql\connector\connection.py", line 395, in _handle_result\n    raise errors.get_exception(packet)\nmysql.connector.errors.ProgrammingError: 1146 (42S02): Table 'datacamp.users' doesn't exist\n\nThe above exception was the direct cause of the following exception:\n\nTraceback (most recent call last):\n  File "C:\Python37\lib\site-packages\discord\ext\commands\bot.py", line 863, in invoke\n    await ctx.command.invoke(ctx)\n  File "C:\Python37\lib\site-packages\discord\ext\commands\core.py", line 728, in invoke\n    await injected(*ctx.args, **ctx.kwargs)\n  File "C:\Python37\lib\site-packages\discord\ext\commands\core.py", line 88, in wrapped\n    raise CommandInvokeError(exc) from exc\ndiscord.ext.commands.errors.CommandInvokeError: Command raised an exception: ProgrammingError: 1146 (42S02): Table 'datacamp.users' doesn't exist\n\n```
Message logged at 01/25/20 20:45:08 by Bot David8#4665 in Channel Direct Message with Vyryn#4618: with Content: Hey Vyryn, there was an error in the command directq: Command raised an exception: ProgrammingError: 1146 (42S02): Table 'datacamp.users' doesn't exist.\n It was used by Vyryn#4618 in V's Private Server, david-bot-testing.
Message logged at 01/25/20 20:45:08 by Bot David8#4665 in Channel Direct Message with Vyryn#4618: with Content: ```py\nTraceback (most recent call last):\n  File "C:\Python37\lib\site-packages\discord\ext\commands\core.py", line 79, in wrapped\n    ret = await coro(*args, **kwargs)\n  File "C:\Users\Vyryn\PycharmProjects\davidbot\cogs\database.py", line 95, in directq\n    result = pquery(query)\n  File "C:\Users\Vyryn\PycharmProjects\davidbot\cogs\database.py", line 22, in pquery\n    cursor.execute(querry)\n  File "C:\Users\Vyryn\PycharmProjects\vbot\venv\lib\site-packages\mysql\connector\cursor.py", line 551, in execute\n    self._handle_result(self._connection.cmd_query(stmt))\n  File "C:\Users\Vyryn\PycharmProjects\vbot\venv\lib\site-packages\mysql\connector\connection.py", line 490, in cmd_query\n    result = self._handle_result(self._send_cmd(ServerCmd.QUERY, query))\n  File "C:\Users\Vyryn\PycharmProjects\vbot\venv\lib\site-packages\mysql\connector\connection.py", line 395, in _handle_result\n    raise errors.get_exception(packet)\nmysql.connector.errors.ProgrammingError: 1146 (42S02): Table 'datacamp.users' doesn't exist\n\nThe above exception was the direct cause of the following exception:\n\nTraceback (most recent call last):\n  File "C:\Python37\lib\site-packages\discord\ext\commands\bot.py", line 863, in invoke\n    await ctx.command.invoke(ctx)\n  File "C:\Python37\lib\site-packages\discord\ext\commands\core.py", line 728, in invoke\n    await injected(*ctx.args, **ctx.kwargs)\n  File "C:\Python37\lib\site-packages\discord\ext\commands\core.py", line 88, in wrapped\n    raise CommandInvokeError(exc) from exc\ndiscord.ext.commands.errors.CommandInvokeError: Command raised an exception: ProgrammingError: 1146 (42S02): Table 'datacamp.users' doesn't exist\n\n```
Message logged at 01/25/20 20:45:59 by Bot David8#4665 in Channel Direct Message with Vyryn#4618: with Content: Hey Vyryn, there was an error in the command adduser: Command raised an exception: KeyError: 'citizen_record'.\n It was used by Vyryn#4618 in V's Private Server, david-bot-testing.
Message logged at 01/25/20 20:45:59 by Bot David8#4665 in Channel Direct Message with Vyryn#4618: with Content: ```py\nTraceback (most recent call last):\n  File "C:\Python37\lib\site-packages\discord\ext\commands\core.py", line 79, in wrapped\n    ret = await coro(*args, **kwargs)\n  File "C:\Users\Vyryn\PycharmProjects\davidbot\cogs\corp.py", line 445, in adduser\n    rsi_number = citizen['citizen_record']\nKeyError: 'citizen_record'\n\nThe above exception was the direct cause of the following exception:\n\nTraceback (most recent call last):\n  File "C:\Python37\lib\site-packages\discord\ext\commands\bot.py", line 863, in invoke\n    await ctx.command.invoke(ctx)\n  File "C:\Python37\lib\site-packages\discord\ext\commands\core.py", line 728, in invoke\n    await injected(*ctx.args, **ctx.kwargs)\n  File "C:\Python37\lib\site-packages\discord\ext\commands\core.py", line 88, in wrapped\n    raise CommandInvokeError(exc) from exc\ndiscord.ext.commands.errors.CommandInvokeError: Command raised an exception: KeyError: 'citizen_record'\n\n```
Message logged at 01/25/20 21:15:54 by Bot David8#4665 in Channel Direct Message with Vyryn#4618: with Content: Hey Vyryn, there was an error in the command listlinks: Command raised an exception: ProgrammingError: 1064 (42000): You have an error in your SQL syntax; check the manual that corresponds to your MariaDB server version for the right syntax to use near '%s)' at line 1.\n It was used by Vyryn#4618 in sample corp server, registration.
Message logged at 01/25/20 21:15:54 by Bot David8#4665 in Channel Direct Message with Vyryn#4618: with Content: ```py\nTraceback (most recent call last):\n  File "C:\Python37\lib\site-packages\discord\ext\commands\core.py", line 79, in wrapped\n    ret = await coro(*args, **kwargs)\n  File "C:\Users\Vyryn\PycharmProjects\davidbot\cogs\corp.py", line 393, in list_rsi_links\n    link = get_rsi(member.id)\n  File "C:\Users\Vyryn\PycharmProjects\davidbot\cogs\database.py", line 44, in get_rsi\n    cursor.execute(query, values)\n  File "C:\Users\Vyryn\PycharmProjects\vbot\venv\lib\site-packages\mysql\connector\cursor.py", line 551, in execute\n    self._handle_result(self._connection.cmd_query(stmt))\n  File "C:\Users\Vyryn\PycharmProjects\vbot\venv\lib\site-packages\mysql\connector\connection.py", line 490, in cmd_query\n    result = self._handle_result(self._send_cmd(ServerCmd.QUERY, query))\n  File "C:\Users\Vyryn\PycharmProjects\vbot\venv\lib\site-packages\mysql\connector\connection.py", line 395, in _handle_result\n    raise errors.get_exception(packet)\nmysql.connector.errors.ProgrammingError: 1064 (42000): You have an error in your SQL syntax; check the manual that corresponds to your MariaDB server version for the right syntax to use near '%s)' at line 1\n\nThe above exception was the direct cause of the following exception:\n\nTraceback (most recent call last):\n  File "C:\Python37\lib\site-packages\discord\ext\commands\bot.py", line 863, in invoke\n    await ctx.command.invoke(ctx)\n  File "C:\Python37\lib\site-packages\discord\ext\commands\core.py", line 728, in invoke\n    await injected(*ctx.args, **ctx.kwargs)\n  File "C:\Python37\lib\site-packages\discord\ext\commands\core.py", line 88, in wrapped\n    raise CommandInvokeError(exc) from exc\ndiscord.ext.commands.errors.CommandInvokeError: Command raised an exception: ProgrammingError: 1064 (42000): You have an error in your SQL syntax; check the manual that corresponds to your MariaDB server version for the right syntax to use near '%s)' at line 1\n\n```
